<?xml version="1.0" ?>
<robot xmlns:xacro="http://www.ros.org/wiki/xacro">

<xacro:property name="connect_offset" value="0.02633" />
<xacro:property name="thigh_offset_y" value="-0.0645" />
<xacro:property name="thigh_offset_z" value="-0.0145" />



<xacro:macro name="phantomx" params="parent *origin">


      <joint name="j_phantomx_attachment" type="fixed">
        <parent link="${parent}"/>
        <child link="MP_BODY"/>
        <xacro:insert_block name="origin" />
      </joint>
      

      <link name="MP_BODY">
        <inertial>
          <origin xyz="0 0 0" />
          <mass value="0.97559947"/>
          <inertia ixx="3.1081800"  ixy="-0.25460189"  ixz="2.0318174" iyy="6.3787776" iyz="0.16417863" izz="5.3316425" />
        </inertial>
        <visual>
          <!--origin xyz="-0.0235 0 -0.03525" rpy="0 0 0" /-->
          <origin xyz="0 0 0" rpy="0 0 0" />
          <geometry>
            <!--box size="0.102 0.109 0.106" /-->
            <mesh filename="package://phantomx_description/meshes/body.STL"  scale="1 1 1"/>
          </geometry>
          <material name="Grey">
            <color rgba="0.20 0.20 0.20 1.0"/>
          </material>
        </visual>
        <collision>
          <origin xyz="0 0 0" rpy="0 0 0" />
          <geometry>
            <mesh filename="package://phantomx_description/meshes/body_coll.STL"  scale="1 1 1"/>
          </geometry>
        </collision>
      </link>

      <gazebo reference="MP_BODY">    
        <material>Gazebo/Grey</material>
      </gazebo>

	   <link name="LIDAR_BOTTOM">
      <!-- Offset the base by half the length of the cylinder -->
      <parent link = "MP_BODY"/>
      <origin xyz=" 0 0 0" rpy=" 0 0 0"/>
      <inertial>
        <mass value="1.2"/>
        <inertia ixx="0.00108773" iyy="0.001087473" izz="0.001092437" ixy="0" ixz="0" iyz="0"/>
      </inertial>
      <collision>
        <geometry>
          <cylinder radius="0.015" length="0.02"/>
        </geometry>
      </collision>
      <!-- The visual is mostly a copy of the collision -->
      <visual>
      <geometry>
          <cylinder radius="0.015" length="0.02"/>
      </geometry>
      </visual>
    </link>
      <!-- Give the base link a unique name -->
    <link name="LIDAR_TOP"> 
      <!-- Offset the top by half the length of the cylinder+base height .05867 -->
      <parent link="LIDAR_BOTTOM"/>
      <origin xyz="0 0 0" rpy=" 0 0 0"/>
      <inertial>
        <mass value="0.1"/>
        <inertia ixx="0.000090623" iyy="0.000090623" izz="0.000091036" ixy="0" ixz="0" iyz="0"/>
      </inertial>
      <collision>
      <geometry>
          <cylinder radius="0.025" length="0.02"/>
      </geometry>
      </collision>
      <visual>
      <geometry>
          <cylinder radius="0.025" length="0.02"/>
      </geometry>
      </visual>
      <!-- Qualify the object as a sensor object -->
      <sensor type="ray" name="sensor">
      <!--Postion the ray sensor based on the specification. Also rotate it 
      by 90 degrees around the X-Axis so that the <horizonal> rays become vertical-->
      <pose xyz="0 0 -0.00245" rpy="1.5707 0 0"/>
      <!-- Enable Visualization of the rays in the GUI-->
      <visualize>true</visualize>
      <!-- Set an update rate of the sensor -->
      <update_rate>30</update_rate>
      <ray>
        <!--Scan element contains horiz and/or vertical beams. No vertical for this-->
        <scan>
          <vertical samples="32" resolution="1" min_angle="-0.53529248" max_angle="0.18622663"/>
        </scan>
        <!-- Range of the beam -->
        <range>
          <min>0.05</min>
          <max>70</max>
          <resolution>0.02</resolution>
        </range>
        <!-- Generate sensor noise (Comment this out if you want an ideal sensor) -->
        <noise>
          <type>gaussian</type>
          <mean>0.0</mean>
          <stddev>0.02</stddev>
        </noise>
      </ray>
      </sensor>
	  </link>

    <!-- Each Joint must have a unique name -->
	  <joint type="revolute" name="lidar_joint">
	   	<!-- Position the joint at the bottom of the top link-->
      <origin xyz="0 0 0.0145" rpy="0 0 0"/>
      <!-- Use the base link as the parent of the joint -->
      <parent link="LIDAR_BOTTOM"/>
      <!--Use the top link as the child of the joint-->
      <child link="LIDAR_TOP"/>
      <!--The axis defines he joint DoF-->
      <axis xyz="0 0 1"/>
        <!--Limit refers to the range of motion of the joint-->
      <limit effort="0" velocity="20" lower="-10000000000000000000000000" upper="10000000000000000000000000"/>
	  </joint>
    <!-- Each Joint must have a unique name -->
	  <joint type="fixed" name="lidar_fix">
	   	<!-- Position the joint at the bottom of the top link-->
      <origin xyz="0.085 0 0.03" rpy="0 0 0"/>
      <!-- Use the base link as the parent of the joint -->
      <parent link="MP_BODY"/>
      <!--Use the top link as the child of the joint-->
      <child link="LIDAR_BOTTOM"/>
	  </joint>

    <gazebo reference="lidar_top">    
      <material>Gazebo/Grey</material>
    </gazebo>  
    <gazebo reference="lidar_bottom">    
      <material>Gazebo/Grey</material>
    </gazebo>

    <xacro:leg_l xyz="0.1248 -0.06164  0.001116"  rpy="0 4.7123 0.7853981633974483" suffix="rf"/>
    <xacro:leg_l xyz="0 -0.1034  0.001116"  rpy="0 4.7123 0" suffix="rm"/>
    <xacro:leg_l xyz="-0.1248 -0.06164  0.001116"  rpy="0 4.7123 -0.7853981633974483" suffix="rr"/>


    <xacro:leg_l xyz="0.1248 0.06164  0.001116"  rpy="0 4.7123 2.356194490192345" suffix="lf"/>
    <xacro:leg_l xyz="0 0.1034  0.001116"  rpy="0 4.7123 3.14159" suffix="lm"/>
    <xacro:leg_l xyz="-0.1248 0.06164  0.001116"  rpy="0 4.7123 3.9269908169872414" suffix="lr"/>

</xacro:macro>





 <xacro:macro name="leg_l" params="xyz rpy suffix">



  <link name="c1_${suffix}">
    <inertial>
      <origin xyz="0 -${connect_offset} 0" rpy="0 0 0"  />
      <mass value="0.024357719"/>
     <inertia ixx="0.0051411124"  ixy="-0.00057530255"  ixz="-0.000024729049" iyy="0.0081915737" iyz="-0.000019223094" izz="0.0011379812" />
    </inertial>
    <visual>
      <origin xyz="0 -0.0252 0" rpy="0 0 0"  />
      <geometry>
        <!--box size="0.045 0.022 0.0325" /-->
        <mesh filename="package://phantomx_description/meshes/connect.STL"  scale="1 1 1"/>
      </geometry>
      <material name="Grey">
        <color rgba="0.20 0.20 0.20 1.0"/>
      </material>
    </visual>
    <collision>
      <origin xyz="0 -${connect_offset} 0" rpy="0 0 0"  />
      <geometry>
        <mesh filename="package://phantomx_description/meshes/connect_coll.STL"  scale="1 1 1"/>
      </geometry>
    </collision>
  </link>


  <link name="c2_${suffix}">
    <inertial>
      <origin xyz="0 -${connect_offset} 0" rpy="0 0 0"  />
      <mass value="0.024357719"/>
     <inertia ixx="0.0051411124"  ixy="-0.00057530255"  ixz="-0.000024729049" iyy="0.0081915737" iyz="-0.000019223094" izz="0.0011379812" />
    </inertial>
    <visual>
      <origin xyz="0 -0.0252 0" rpy="0 0 0"  />
      <geometry>
        <!--box size="0.045 0.022 0.0325" /-->
        <mesh filename="package://phantomx_description/meshes/connect.STL"  scale="1 1 1"/>
      </geometry>
      <material name="Grey">
        <color rgba="0.20 0.20 0.20 1.0"/>
      </material>
    </visual>
    <collision>
      <origin xyz="0 -${connect_offset} 0" rpy="0 0 0"  />
      <geometry>
        <mesh filename="package://phantomx_description/meshes/connect_coll.STL"  scale="1 1 1"/>
      </geometry>
    </collision>
  </link>



  <link name="thigh_${suffix}">
    <inertial>
      <origin xyz="0 0 0" rpy="0 0 0"  />
      <mass value="0.024357719"/>
     <inertia ixx="0.0051411124"  ixy="-0.00057530255"  ixz="-0.000024729049" iyy="0.0081915737" iyz="-0.000019223094" izz="0.0011379812" />
    </inertial>
    <visual>
      <origin xyz="0 0 0" rpy="0 0 0"  />
      <geometry>
        <!--box size="0.045 0.022 0.0325" /-->
        <mesh filename="package://phantomx_description/meshes/thigh_l.STL"  scale="1 1 1"/>
      </geometry>
      <material name="Grey">
        <color rgba="0.20 0.20 0.20 1.0"/>
      </material>
    </visual>
    <collision>
      <origin xyz="0 0 0" rpy="0 0 0"  />
      <geometry>
        <mesh filename="package://phantomx_description/meshes/thigh_l_coll.STL"  scale="1 1 1"/>
      </geometry>
    </collision>
  </link>



  <link name="tibia_${suffix}">
    <inertial>
      <origin xyz="0 0 0" rpy="0 0 0"  />
      <mass value="0.024357719"/>
     <inertia ixx="0.0051411124"  ixy="-0.00057530255"  ixz="-0.000024729049" iyy="0.0081915737" iyz="-0.000019223094" izz="0.0011379812" />
    </inertial>
    <visual>
      <origin xyz="0 0 0" rpy="0 0 0"  />
      <geometry>
        <!--box size="0.045 0.022 0.0325" /-->
        <mesh filename="package://phantomx_description/meshes/tibia_l.STL"  scale="1 1 1"/>
      </geometry>
      <material name="Grey">
        <color rgba="0.20 0.20 0.20 1.0"/>
      </material>
    </visual>
    <collision>
      <origin xyz="0 0 0" rpy="0 0 0"  />
      <geometry>
        <mesh filename="package://phantomx_description/meshes/tibia_l_coll.STL"  scale="1 1 1"/>
      </geometry>
    </collision>
  </link>



  <joint name="j_c1_${suffix}" type="revolute">
    <parent link="MP_BODY"/>
    <child link="c1_${suffix}"/>
    <origin xyz="${xyz}" rpy="${rpy}" />
    <axis xyz="1 0 0" />
    <limit effort="2.8" velocity="5.6548668" lower="-2.6179939" upper="2.6179939" />
  </joint>

  <joint name="j_c2_${suffix}" type="fixed">
    <parent link="c1_${suffix}"/>
    <child link="c2_${suffix}"/>
    <origin xyz="0 -0.054 0" rpy="0 1.5704 3.14159" />
  </joint>


  <joint name="j_thigh_${suffix}" type="revolute">
    <parent link="c2_${suffix}"/>
    <child link="thigh_${suffix}"/>
    <origin xyz="0 0 0" rpy=" 0 3.14159 3.14159" />
    <axis xyz="1 0 0" />
    <limit effort="2.8" velocity="5.6548668" lower="-2.6179939" upper="2.6179939" />
  </joint>

  <joint name="j_tibia_${suffix}" type="revolute">
    <parent link="thigh_${suffix}"/>
    <child link="tibia_${suffix}"/>
    <origin xyz="0 ${thigh_offset_y} ${thigh_offset_z}" rpy="-1.5707 0 3.14159" />
    <axis xyz="1 0 0" />
    <limit effort="2.8" velocity="5.6548668" lower="-2.6179939" upper="2.6179939" />
  </joint>



   <transmission name="t_c1_${suffix}">
    <type>transmission_interface/SimpleTransmission</type>
    <joint name="j_c1_${suffix}">
      <hardwareInterface>EffortJointInterface</hardwareInterface>    
    </joint>
    <actuator name="m_c1_${suffix}">
      <hardwareInterface>EffortJointInterface</hardwareInterface>
      <mechanicalReduction>1</mechanicalReduction>
    </actuator>
  </transmission>


   <transmission name="t_thigh_${suffix}">
    <type>transmission_interface/SimpleTransmission</type>
    <joint name="j_thigh_${suffix}">
      <hardwareInterface>EffortJointInterface</hardwareInterface>    
    </joint>
    <actuator name="m_thigh_${suffix}">
      <hardwareInterface>EffortJointInterface</hardwareInterface>
      <mechanicalReduction>1</mechanicalReduction>
    </actuator>
  </transmission>


   <transmission name="t_tibia_${suffix}">
    <type>transmission_interface/SimpleTransmission</type>
    <joint name="j_tibia_${suffix}">
      <hardwareInterface>EffortJointInterface</hardwareInterface>
    </joint>
    <actuator name="m_tibia_${suffix}">
      <hardwareInterface>EffortJointInterface</hardwareInterface>
      <mechanicalReduction>1</mechanicalReduction>
    </actuator>
  </transmission>



  <gazebo reference="c1_${suffix}">    
    <material>Gazebo/Grey</material>
  </gazebo>

  <gazebo reference="c2_${suffix}">    
    <material>Gazebo/Grey</material>
  </gazebo>

  <gazebo reference="thigh_${suffix}">    
    <material>Gazebo/Grey</material>
  </gazebo>

  <gazebo reference="tibia_${suffix}">    
    <material>Gazebo/Grey</material>
  </gazebo>

  
</xacro:macro>





</robot>
